<?xml version="1.0" encoding="utf-8"?>
<!-- This URDF was automatically created by SolidWorks to URDF Exporter! Originally created by Stephen Brawner (brawner@gmail.com) 
     Commit Version: 1.5.1-0-g916b5db  Build Version: 1.5.7152.31018
     For more information, please see http://wiki.ros.org/sw_urdf_exporter -->
<robot name="yutu" xmlns:xacro="http://www.ros.org/wiki/xacro">
  
  <link name="base_footprint">
		<visual>
			<origin xyz="0 0 0" rpy="0 0 0" />
			<geometry>
				<box size="0.001 0.001 0.001" />
			</geometry>
		</visual>
	</link>

  <link name="base_link">
    <inertial>
      <origin
        xyz="0.00071321191683138 -1.42644557277194E-09 0.194748532484259"
        rpy="0 0 0" />
      <mass
        value="0.5" />
      <inertia
        ixx="5.19900695904901"
        ixy="-2.63810509598704E-07"
        ixz="-0.00103069519824648"
        iyy="12.8692383637623"
        iyz="3.01074544522759E-08"
        izz="15.8810925722298" />
    </inertial>
    <visual>
      <origin
        xyz="0 0 0"
        rpy="0 0 0" />
      <geometry>
        <mesh
          filename="package://yutu_description/meshes/base_link.STL" />
      </geometry>
      <material
        name="">
        <color
          rgba="1 1 1 1" />
      </material>
    </visual>
    <collision>
      <origin
        xyz="0 0 0"
        rpy="0 0 0" />
      <geometry>
        <mesh
          filename="package://yutu_description/meshes/base_link.STL" />
      </geometry>
    </collision>
  </link>

  <joint name="base_link_joint" type="fixed">
    <origin xyz="0 0 0" rpy="0 0 0" />
    <parent link="base_footprint" />
    <child link="base_link" />
  </joint>

  <link
    name="camera_link">
    <inertial>
      <origin
        xyz="0.00116205106935885 -0.000637806704274199 -0.0346889866480825"
        rpy="0 0 0" />
      <mass
        value="0.001" />
      <inertia
        ixx="0.0244919073431695"
        ixy="0.000188391967068734"
        ixz="9.87614358049783E-07"
        iyy="0.00739705746144106"
        iyz="1.42536081881259E-05"
        izz="0.0293966166562696" />
    </inertial>
    <visual>
      <origin
        xyz="0 0 0"
        rpy="0 0 0" />
      <geometry>
        <mesh
          filename="package://yutu_description/meshes/camera_link.STL" />
      </geometry>
      <material
        name="">
        <color
          rgba="0.698039215686274 0.698039215686274 0.698039215686274 1" />
      </material>
    </visual>
    <collision>
      <origin
        xyz="0 0 0"
        rpy="0 0 0" />
      <geometry>
        <mesh
          filename="package://yutu_description/meshes/camera_link.STL" />
      </geometry>
    </collision>
  </link>
  <joint
    name="camera_joint"
    type="fixed">
    <origin
      xyz="0.365 0 0.84"
      rpy="0 0 0" />
    <parent
      link="base_link" />
    <child
      link="camera_link" />
    <axis
      xyz="0 0 0" />
  </joint>

  <link
    name="laser_link">
    <inertial>
      <origin
        xyz="0.0113215162879861 0.000897637918713154 -5.46175478177702E-06"
        rpy="0 0 0" />
      <mass
        value="0.001" />
      <inertia
        ixx="0.000443668821575738"
        ixy="1.70454612828059E-05"
        ixz="6.97380639795373E-08"
        iyy="0.000229903137291981"
        iyz="5.32526352270249E-09"
        izz="0.000228534291396077" />
    </inertial>
    <visual>
      <origin
        xyz="0 0 0"
        rpy="0 0 0" />
      <geometry>
        <mesh
          filename="package://yutu_description/meshes/laser_link.STL" />
      </geometry>
      <material
        name="">
        <color
          rgba="0.796078431372549 0.823529411764706 0.937254901960784 1" />
      </material>
    </visual>
    <collision>
      <origin
        xyz="0 0 0"
        rpy="0 0 0" />
      <geometry>
        <mesh
          filename="package://yutu_description/meshes/laser_link.STL" />
      </geometry>
    </collision>
  </link>
  <joint
    name="laser_joint"
    type="fixed">
    <origin
      xyz="0.39 0.0 0.65"
      rpy="0 0 0" />
    <parent
      link="base_link" />
    <child
      link="laser_link" />
    <axis
      xyz="0 0 0" />
  </joint>

  <link
    name="right_up_link">
    <inertial>
      <origin
        xyz="-0.133682843719937 0.0577612791933153 -0.187149802845539"
        rpy="0 0 0" />
      <mass
        value="0.001" />
      <inertia
        ixx="0.00268978246384689"
        ixy="-7.05662749970002E-07"
        ixz="-0.00037200145756455"
        iyy="0.0169407030683164"
        iyz="5.32530155029341E-06"
        izz="0.0148890084379899" />
    </inertial>
    <visual>
      <origin
        xyz="0 0 0"
        rpy="0 0 0" />
      <geometry>
        <mesh
          filename="package://yutu_description/meshes/right_up_link.STL" />
      </geometry>
      <material
        name="">
        <color
          rgba="0.792156862745098 0.819607843137255 0.933333333333333 1" />
      </material>
    </visual>
    <collision>
      <origin
        xyz="0 0 0"
        rpy="0 0 0" />
      <geometry>
        <mesh
          filename="package://yutu_description/meshes/right_up_link.STL" />
      </geometry>
    </collision>
  </link>
  <joint
    name="right_up_joint"
    type="fixed">
    <origin
      xyz="-0.1 -0.33 0.13"
      rpy="0 0 0" />
    <parent
      link="base_link" />
    <child
      link="right_up_link" />
    <axis
      xyz="0 -1 0" />
  </joint>
  <link
    name="right_down_link">
    <inertial>
      <origin
        xyz="0.0589056693041921 0.0411549760280981 -0.0773029247285448"
        rpy="0 0 0" />
      <mass
        value="0.001" />
      <inertia
        ixx="0.00205649621796634"
        ixy="-1.34648561119581E-06"
        ixz="-0.001980615647894"
        iyy="0.0101031814166522"
        iyz="5.36273615245661E-06"
        izz="0.00907589706967638" />
    </inertial>
    <visual>
      <origin
        xyz="0 0 0"
        rpy="0 0 0" />
      <geometry>
        <mesh
          filename="package://yutu_description/meshes/right_down_link.STL" />
      </geometry>
      <material
        name="">
        <color
          rgba="0.792156862745098 0.819607843137255 0.933333333333333 1" />
      </material>
    </visual>
    <collision>
      <origin
        xyz="0 0 0"
        rpy="0 0 0" />
      <geometry>
        <mesh
          filename="package://yutu_description/meshes/right_down_link.STL" />
      </geometry>
    </collision>
  </link>
  <joint
    name="right_down_joint"
    type="fixed">
    <origin
      xyz="0.20 -0.0425 -0.17"
      rpy="0 0 0" />
    <parent
      link="right_up_link" />
    <child
      link="right_down_link" />
    <axis
      xyz="0 -1 0" />
  </joint>
  <link
    name="right_front_wheel_link">
    <inertial>
      <origin
        xyz="4.64284670953496E-06 0.00942941401983621 -1.43666265051134E-07"
        rpy="0 0 0" />
      <mass
        value="0.5" />
      <inertia
        ixx="0.00840548058918848"
        ixy="1.89174517411822E-06"
        ixz="1.17966662648947E-08"
        iyy="0.0129971850007653"
        iyz="-3.10884996692571E-08"
        izz="0.00840556176326334" />
    </inertial>
    <visual>
      <origin
        xyz="0 0 0"
        rpy="0 0 0" />
      <geometry>
        <mesh
          filename="package://yutu_description/meshes/right_front_wheel_link.STL" />
      </geometry>
      <material
        name="">
        <color
          rgba="0.647058823529412 0.619607843137255 0.588235294117647 1" />
      </material>
    </visual>
    <collision>
      <origin
        xyz="0 0 0"
        rpy="0 0 0" />
      <geometry>
        <mesh
          filename="package://yutu_description/meshes/right_front_wheel_link.STL" />
      </geometry>
    </collision>
  </link>
  <joint
    name="right_front_wheel_joint"
    type="continuous">
    <origin
      xyz="0.24 -0.1 -0.1"
      rpy="0 0 0" />
    <parent
      link="right_down_link" />
    <child
      link="right_front_wheel_link" />
    <axis
      xyz="0 1 0" />
  </joint>
  <link
    name="right_middle_wheel_link">
    <inertial>
      <origin
        xyz="6.53594576349725E-07 0.00942941515421114 -4.71784419892041E-07"
        rpy="0 0 0" />
      <mass
        value="0.5" />
      <inertia
        ixx="0.00840550186325641"
        ixy="-1.37181018108473E-10"
        ixz="3.82031935440113E-08"
        iyy="0.0129971857076584"
        iyz="-2.71638821395339E-09"
        izz="0.00840553957033001" />
    </inertial>
    <visual>
      <origin
        xyz="0 0 0"
        rpy="0 0 0" />
      <geometry>
        <mesh
          filename="package://yutu_description/meshes/right_middle_wheel_link.STL" />
      </geometry>
      <material
        name="">
        <color
          rgba="0.647058823529412 0.619607843137255 0.588235294117647 1" />
      </material>
    </visual>
    <collision>
      <origin
        xyz="0 0 0"
        rpy="0 0 0" />
      <geometry>
        <mesh
          filename="package://yutu_description/meshes/right_middle_wheel_link.STL" />
      </geometry>
    </collision>
  </link>
  <joint
    name="right_middle_wheel_joint"
    type="continuous">
    <origin
      xyz="-0.11 -0.14 -0.1"
      rpy="0 0 0" />
    <parent
      link="right_down_link" />
    <child
      link="right_middle_wheel_link" />
    <axis
      xyz="0 1 0" />
  </joint>
  <link
    name="right_rear_wheel_link">
    <inertial>
      <origin
        xyz="4.24657688493899E-05 0.00913638080449108 1.25729732489144E-06"
        rpy="0 0 0" />
      <mass
        value="0.5" />
      <inertia
        ixx="0.00839712148060717"
        ixy="2.12442196231524E-05"
        ixz="-2.75477006440965E-08"
        iyy="0.0129970395829342"
        iyz="2.83185117280476E-07"
        izz="0.0083969605315725" />
    </inertial>
    <visual>
      <origin
        xyz="0 0 0"
        rpy="0 0 0" />
      <geometry>
        <mesh
          filename="package://yutu_description/meshes/right_rear_wheel_link.STL" />
      </geometry>
      <material
        name="">
        <color
          rgba="0.647058823529412 0.619607843137255 0.588235294117647 1" />
      </material>
    </visual>
    <collision>
      <origin
        xyz="0 0 0"
        rpy="0 0 0" />
      <geometry>
        <mesh
          filename="package://yutu_description/meshes/right_rear_wheel_link.STL" />
      </geometry>
    </collision>
  </link>
  <joint
    name="right_rear_wheel_joint"
    type="continuous">
    <origin
      xyz="-0.26 -0.1 -0.27"
      rpy="0 0 0" />
    <parent
      link="right_up_link" />
    <child
      link="right_rear_wheel_link" />
    <axis
      xyz="0 1 0" />
  </joint>
  <link
    name="left_up_link">
    <inertial>
      <origin
        xyz="-0.137454925023346 -0.0527605358332723 -0.184523796804967"
        rpy="0 0 0" />
      <mass
        value="0.001" />
      <inertia
        ixx="0.00267995590511413"
        ixy="-7.14355042850304E-07"
        ixz="-0.000135453356567795"
        iyy="0.0169406951926897"
        iyz="-5.34805295074904E-06"
        izz="0.0148988393864407" />
    </inertial>
    <visual>
      <origin
        xyz="0 0 0"
        rpy="0 0 0" />
      <geometry>
        <mesh
          filename="package://yutu_description/meshes/left_up_link.STL" />
      </geometry>
      <material
        name="">
        <color
          rgba="0.792156862745098 0.819607843137255 0.933333333333333 1" />
      </material>
    </visual>
    <collision>
      <origin
        xyz="0 0 0"
        rpy="0 0 0" />
      <geometry>
        <mesh
          filename="package://yutu_description/meshes/left_up_link.STL" />
      </geometry>
    </collision>
  </link>
  <joint
    name="left_up_joint"
    type="fixed">
    <origin
      xyz="-0.1 0.33 0.13"
      rpy="0 0 0" />
    <parent
      link="base_link" />
    <child
      link="left_up_link" />
    <axis
      xyz="0 1 0" />
  </joint>
  <link
    name="left_down_link">
    <inertial>
      <origin
        xyz="0.0602474623708353 -0.0411474122848515 -0.0759036611264567"
        rpy="0 0 0" />
      <mass
        value="0.001" />
      <inertia
        ixx="0.00215405410618268"
        ixy="6.19228600289598E-07"
        ixz="-0.00214914411877823"
        iyy="0.0101031625149077"
        iyz="-6.76706335895392E-06"
        izz="0.00897835931140362" />
    </inertial>
    <visual>
      <origin
        xyz="0 0 0"
        rpy="0 0 0" />
      <geometry>
        <mesh
          filename="package://yutu_description/meshes/left_down_link.STL" />
      </geometry>
      <material
        name="">
        <color
          rgba="0.792156862745098 0.819607843137255 0.933333333333333 1" />
      </material>
    </visual>
    <collision>
      <origin
        xyz="0 0 0"
        rpy="0 0 0" />
      <geometry>
        <mesh
          filename="package://yutu_description/meshes/left_down_link.STL" />
      </geometry>
    </collision>
  </link>
  <joint
    name="left_down_joint"
    type="fixed">
    <origin
      xyz="0.2 0.0425 -0.17"
      rpy="0 0 0" />
    <parent
      link="left_up_link" />
    <child
      link="left_down_link" />
    <axis
      xyz="0 -1 0" />
  </joint>
  <link
    name="left_front_wheel_link">
    <inertial>
      <origin
        xyz="1.87019869205551E-05 0.000570279508203708 1.98274949236854E-08"
        rpy="0 0 0" />
      <mass
        value="0.5" />
      <inertia
        ixx="0.00841003424237453"
        ixy="0.000144539985326821"
        ixz="4.10226380237494E-08"
        iyy="0.0129926311806184"
        iyz="9.29460178780097E-07"
        izz="0.00840556205430822" />
    </inertial>
    <visual>
      <origin
        xyz="0 0 0"
        rpy="0 0 0" />
      <geometry>
        <mesh
          filename="package://yutu_description/meshes/left_front_wheel_link.STL" />
      </geometry>
      <material
        name="">
        <color
          rgba="0.647058823529412 0.619607843137255 0.588235294117647 1" />
      </material>
    </visual>
    <collision>
      <origin
        xyz="0 0 0"
        rpy="0 0 0" />
      <geometry>
        <mesh
          filename="package://yutu_description/meshes/left_front_wheel_link.STL" />
      </geometry>
    </collision>
  </link>
  <joint
    name="left_front_wheel_joint"
    type="continuous">
    <origin
      xyz="0.24 0.1 -0.1"
      rpy="0 0 0" />
    <parent
      link="left_down_link" />
    <child
      link="left_front_wheel_link" />
    <axis
      xyz="0 1 0" />
  </joint>
  <link
    name="left_middle_wheel_link">
    <inertial>
      <origin
        xyz="4.92480116243144E-07 0.000570584817673803 -6.35839474488753E-07"
        rpy="0 0 0" />
      <mass
        value="0.5" />
      <inertia
        ixx="0.00840552706975302"
        ixy="1.59485741930329E-09"
        ixz="4.21279830351304E-08"
        iyy="0.0129971857057505"
        iyz="2.97484462961539E-09"
        izz="0.00840551436168273" />
    </inertial>
    <visual>
      <origin
        xyz="0 0 0"
        rpy="0 0 0" />
      <geometry>
        <mesh
          filename="package://yutu_description/meshes/left_middle_wheel_link.STL" />
      </geometry>
      <material
        name="">
        <color
          rgba="0.647058823529412 0.619607843137255 0.588235294117647 1" />
      </material>
    </visual>
    <collision>
      <origin
        xyz="0 0 0"
        rpy="0 0 0" />
      <geometry>
        <mesh
          filename="package://yutu_description/meshes/left_middle_wheel_link.STL" />
      </geometry>
    </collision>
  </link>
  <joint
    name="left_middle_wheel_joint"
    type="continuous">
    <origin
      xyz="-0.11 0.14 -0.1"
      rpy="0 0 0" />
    <parent
      link="left_down_link" />
    <child
      link="left_middle_wheel_link" />
    <axis
      xyz="0 1 0" />
  </joint>
  <link
    name="left_rear_wheel_link">
    <inertial>
      <origin
        xyz="8.48656343746187E-07 0.000863520454164046 5.50041836772097E-07"
        rpy="0 0 0" />
      <mass
        value="0.5" />
      <inertia
        ixx="0.00839698893882276"
        ixy="1.14322974878158E-06"
        ixz="-4.24649884619474E-08"
        iyy="0.0129971372535242"
        iyz="-7.27203296450212E-09"
        izz="0.00839699493737667" />
    </inertial>
    <visual>
      <origin
        xyz="0 0 0"
        rpy="0 0 0" />
      <geometry>
        <mesh
          filename="package://yutu_description/meshes/left_rear_wheel_link.STL" />
      </geometry>
      <material
        name="">
        <color
          rgba="0.647058823529412 0.619607843137255 0.588235294117647 1" />
      </material>
    </visual>
    <collision>
      <origin
        xyz="0 0 0"
        rpy="0 0 0" />
      <geometry>
        <mesh
          filename="package://yutu_description/meshes/left_rear_wheel_link.STL" />
      </geometry>
    </collision>
  </link>

  <joint name="left_rear_wheel_joint" type="continuous">
    <origin
      xyz="-0.26 0.1 -0.27"
      rpy="0 0 0" />
    <parent
      link="left_up_link" />
    <child
      link="left_rear_wheel_link" />
    <axis
      xyz="0 1 0" />
  </joint>

  <joint name="imu_joint" type="fixed">
    <origin xyz="0.393474958757372 0.00225655709560415 0.7" rpy="0 0 0" />
    <parent link="base_link"/>
    <child link="imu_link"/>
  </joint>

  <link name="imu_link">
    <collision>
        <geometry>
            <box size="0.01 0.01 0.01" />
        </geometry>
        <origin xyz="0.0 0.0 0" rpy="0.0 0.0 0.0" />
    </collision>
  </link>

  <xacro:include filename="$(find yutu_description)/urdf/xacro/sensor_high.xacro" />
  <xacro:include filename="$(find yutu_description)/urdf/xacro/xmaterials.xacro" />

</robot>